Traceback (most recent call last):
  File "RunServer.py", line 6, in <module>
    from resources.ProfileImage import ChangeProfileImage
  File "/home/ubuntu/Server_For-Competition_Jaehoon/AdditNew/Server_For-Competition/Flask/app/resources/ProfileImage.py", line 3
    from pymongo
               ^
SyntaxError: invalid syntax
Error in sys.excepthook:
Traceback (most recent call last):
  File "/usr/lib/python3/dist-packages/apport_python_hook.py", line 63, in apport_excepthook
    from apport.fileutils import likely_packaged, get_recent_crashes
  File "/usr/lib/python3/dist-packages/apport/__init__.py", line 5, in <module>
    from apport.report import Report
  File "/usr/lib/python3/dist-packages/apport/report.py", line 30, in <module>
    import apport.fileutils
  File "/usr/lib/python3/dist-packages/apport/fileutils.py", line 23, in <module>
    from apport.packaging_impl import impl as packaging
  File "/usr/lib/python3/dist-packages/apport/packaging_impl.py", line 23, in <module>
    import apt
  File "/usr/lib/python3/dist-packages/apt/__init__.py", line 23, in <module>
    import apt_pkg
ModuleNotFoundError: No module named 'apt_pkg'

Original exception was:
Traceback (most recent call last):
  File "RunServer.py", line 6, in <module>
    from resources.ProfileImage import ChangeProfileImage
  File "/home/ubuntu/Server_For-Competition_Jaehoon/AdditNew/Server_For-Competition/Flask/app/resources/ProfileImage.py", line 3
    from pymongo
               ^
SyntaxError: invalid syntax
